Workbook

Sheet Diagrama ER (corregido)

Sheet Inventario Modelo Lógico (corre
A1: Tablas resultantes del Diccionario Genérico (Modelo Lógico)
A2: # | B2: Tabla | C2: Descripción Tabla | D2: Observaciones
A3: 1 | B3: programa_academico | C3: Catálogo de programas académicos ofrecidos por la institución | D3: PK: id_programa | UK: codigo
A4: 2 | B4: habilidad | C4: Catálogo de habilidades que los usuarios pueden asociar a su perfil | D4: PK: id_habilidad | UK: nombre
A5: 3 | B5: interes | C5: Catálogo de áreas de interés disponibles para los usuarios | D5: PK: id_interes | UK: nombre
A6: 4 | B6: empresa | C6: Empresas registradas en la plataforma para publicar ofertas laborales | D6: PK: id_empresa
A7: 5 | B7: usuario | C7: Supertipo que agrupa a todos los tipos de usuarios de la red social | D7: PK: id_usuario | UK: email
A8: 6 | B8: estudiante | C8: Subtipo de usuario: estudiante activo de la institución | D8: PK: id_usuario | FK: id_usuario, id_programa
A9: 7 | B9: docente | C9: Subtipo de usuario: docente vinculado a la institución | D9: PK: id_usuario | FK: id_usuario
A10: 8 | B10: empleado | C10: Subtipo de usuario: empleado administrativo de la institución | D10: PK: id_usuario | FK: id_usuario
A11: 9 | B11: egresado | C11: Subtipo de usuario: graduado de la institución | D11: PK: id_usuario | FK: id_usuario, id_programa
A12: 10 | B12: publico_general | C12: Subtipo de usuario: persona externa sin vínculo institucional formal | D12: PK: id_usuario | FK: id_usuario
A13: 11 | B13: usuario_habilidad | C13: Tabla pivote N:M entre usuario y habilidad | D13: PK compuesta: id_usuario + id_habilidad
A14: 12 | B14: usuario_interes | C14: Tabla pivote N:M entre usuario y área de interés | D14: PK compuesta: id_usuario + id_interes
... A32: 30 | B32: reporte | C32: Reportes de contenido inapropiado realizados por usuarios | D32: PK: id_reporte | FK: id_reportante

Sheet Tipos de Dato
A1: Tipos de Datos - Tabla Comparativa
A2: # | B2: Tipo de Dato Genérico | C2: Tipos de Dato - PosgreSQL
A3: 1 | B3: AUTOINCREMENTABLE | C3: SERIAL
A4: 2 | B4: UUID | C4: UUID
A5: 3 | B5: ENTERO | C5: INT / SMALLINT
A6: 4 | B6: DECIMAL | C6: NUMERIC(p,s)
A7: 5 | B7: LÓGICO | C7: BOOLEAN
A8: 6 | B8: TEXTO | C8: TEXT
A9: 7 | B9: CARACTER | C9: VARCHAR(n)
A10: 8 | B10: FECHA | C10: DATE
A11: 9 | B11: FECHA_HORA | C11: TIMESTAMP
A12: 10 | B12: IMAGEN | C12: VARCHAR(255) — URL externa
A13: 11 | B13: AUDIO | C13: VARCHAR(255) — URL externa
A14: 12 | B14: URL | C14: VARCHAR(255)
... A18: 16 | B18: JSON | C18: JSONB

Sheet DICCIONARIO DATOS (Físico)
A2: DICCIONARIO DE DATOS FÍSICO — Red Social Estudiantil Pascualina
A3: INVENTARIO DE TABLAS
A4: # | B4: Tabla | C4: Descripción Tabla
A5: 1 | B5: ='Inventario Modelo Lógico (corre'!B3 -> programa_academico | C5: ='Inventario Modelo Lógico (corre'!C3 -> Catálogo de programas académicos ofrecidos por la institución
A6: 2 | B6: ='Inventario Modelo Lógico (corre'!B4 -> habilidad | C6: ='Inventario Modelo Lógico (corre'!C4 -> Catálogo de habilidades que los usuarios pueden asociar a su perfil
A7: 3 | B7: ='Inventario Modelo Lógico (corre'!B5 -> interes | C7: ='Inventario Modelo Lógico (corre'!C5 -> Catálogo de áreas de interés disponibles para los usuarios
A8: 4 | B8: ='Inventario Modelo Lógico (corre'!B6 -> empresa | C8: ='Inventario Modelo Lógico (corre'!C6 -> Empresas registradas en la plataforma para publicar ofertas laborales
A9: 5 | B9: ='Inventario Modelo Lógico (corre'!B7 -> usuario | C9: ='Inventario Modelo Lógico (corre'!C7 -> Supertipo que agrupa a todos los tipos de usuarios de la red social
A10: 6 | B10: ='Inventario Modelo Lógico (corre'!B8 -> estudiante | C10: ='Inventario Modelo Lógico (corre'!C8 -> Subtipo de usuario: estudiante activo de la institución
A11: 7 | B11: ='Inventario Modelo Lógico (corre'!B9 -> docente | C11: ='Inventario Modelo Lógico (corre'!C9 -> Subtipo de usuario: docente vinculado a la institución
A12: 8 | B12: ='Inventario Modelo Lógico (corre'!B10 -> empleado | C12: ='Inventario Modelo Lógico (corre'!C10 -> Subtipo de usuario: empleado administrativo de la institución
A13: 9 | B13: ='Inventario Modelo Lógico (corre'!B11 -> egresado | C13: ='Inventario Modelo Lógico (corre'!C11 -> Subtipo de usuario: graduado de la institución
A14: 10 | B14: ='Inventario Modelo Lógico (corre'!B12 -> publico_general | C14: ='Inventario Modelo Lógico (corre'!C12 -> Subtipo de usuario: persona externa sin vínculo institucional formal
A15: 11 | B15: ='Inventario Modelo Lógico (corre'!B13 -> usuario_habilidad | C15: ='Inventario Modelo Lógico (corre'!C13 -> Tabla pivote N:M entre usuario y habilidad
A16: 12 | B16: ='Inventario Modelo Lógico (corre'!B14 -> usuario_interes | C16: ='Inventario Modelo Lógico (corre'!C14 -> Tabla pivote N:M entre usuario y área de interés
... A34: 30 | B34: ='Inventario Modelo Lógico (corre'!B32 -> reporte | C34: ='Inventario Modelo Lógico (corre'!C32 -> Reportes de contenido inapropiado realizados por usuarios
A36: TABLAS EN DETALLE
A37: 1 | B37: Tabla | C37: =B5 -> programa_academico | E37: Descripción Tabla | G37: =C5 -> Catálogo de programas académicos ofrecidos por la institución | K37: Versión | L37: 1
A38: # | B38: Campo | C38: Descripción Campo | D38: Tipo Genérico | E38: Tipo PostgreSQL | F38: Tamaño | G38: Nulo | H38: PK | I38: FK | J38: UK | K38: Nota/Comentarios
A39: 1 | B39: id_programa | C39: Identificador único del programa | D39: AUTOINCREMENTABLE | E39: SERIAL | F39: SERIAL | G39: No | H39: S | K39: PK autoincremental
A40: 2 | B40: codigo | C40: Código institucional del programa | D40: CARACTER | E40: VARCHAR(20) | F40: VARCHAR(20) | G40: No | J40: S | K40: Valor único
A41: 3 | B41: nombre | C41: Nombre completo del programa académico | D41: CARACTER | E41: VARCHAR(150) | F41: VARCHAR(150) | G41: No
A42: 4 | B42: facultad | C42: Facultad a la que pertenece el programa | D42: CARACTER | E42: VARCHAR(100) | F42: VARCHAR(100)
A43: 5 | B43: nivel | C43: Nivel académico (pregrado, posgrado, etc) | D43: CARACTER | E43: VARCHAR(50) | F43: VARCHAR(50)
A45: 2 | B45: Tabla | C45: =B6 -> habilidad | E45: Descripción Tabla | G45: =C6 -> Catálogo de habilidades que los usuarios pueden asociar a su perfil | K45: Versión | L45: 1
A46: # | B46: Campo | C46: Descripción Campo | D46: Tipo Genérico | E46: Tipo PostgreSQL | F46: Tamaño | G46: Nulo | H46: PK | I46: FK | J46: UK | K46: Nota/Comentarios
A47: 1 | B47: id_habilidad | C47: Identificador único de la habilidad | D47: AUTOINCREMENTABLE | E47: SERIAL | F47: SERIAL | G47: No | H47: S | K47: PK autoincremental
A48: 2 | B48: nombre | C48: Nombre de la habilidad | D48: CARACTER | E48: VARCHAR(100) | F48: VARCHAR(100) | G48: No | J48: S | K48: Valor único
A49: 3 | B49: categoria | C49: Categoría temática de la habilidad | D49: CARACTER | E49: VARCHAR(100) | F49: VARCHAR(100)
A51: 3 | B51: Tabla | C51: =B7 -> interes | E51: Descripción Tabla | G51: =C7 -> Catálogo de áreas de interés disponibles para los usuarios | K51: Versión | L51: 1
A52: # | B52: Campo | C52: Descripción Campo | D52: Tipo Genérico | E52: Tipo PostgreSQL | F52: Tamaño | G52: Nulo | H52: PK | I52: FK | J52: UK | K52: Nota/Comentarios
A53: 1 | B53: id_interes | C53: Identificador único del interés | D53: AUTOINCREMENTABLE | E53: SERIAL | F53: SERIAL | G53: No | H53: S | K53: PK autoincremental
A54: 2 | B54: nombre | C54: Nombre del área de interés | D54: CARACTER | E54: VARCHAR(100) | F54: VARCHAR(100) | G54: No | J54: S | K54: Valor único
A55: 3 | B55: categoria | C55: Categoría temática del interés | D55: CARACTER | E55: VARCHAR(100) | F55: VARCHAR(100)
A57: 4 | B57: Tabla | C57: =B8 -> empresa | E57: Descripción Tabla | G57: =C8 -> Empresas registradas en la plataforma para publicar ofertas laborales | K57: Versión | L57: 1
A58: # | B58: Campo | C58: Descripción Campo | D58: Tipo Genérico | E58: Tipo PostgreSQL | F58: Tamaño | G58: Nulo | H58: PK | I58: FK | J58: UK | K58: Nota/Comentarios
A59: 1 | B59: id_empresa | C59: Identificador único de la empresa | D59: AUTOINCREMENTABLE | E59: SERIAL | F59: SERIAL | G59: No | H59: S | K59: PK autoincremental
A60: 2 | B60: nombre | C60: Nombre o razón social de la empresa | D60: CARACTER | E60: VARCHAR(150) | F60: VARCHAR(150) | G60: No
A61: 3 | B61: descripcion | C61: Descripción general de la empresa | D61: TEXTO | E61: TEXT | F61: TEXT
A62: 4 | B62: sitio_web | C62: URL del sitio web corporativo | D62: URL | E62: VARCHAR(255) | F62: VARCHAR(255)
...
